Workbook

Sheet MB_Header_CC
A1: API10 | B1: uwi | C1: lease_name | D1: well_name | E1: well_num | F1: operator | G1: rsv_cat | H1: bench_cc | I1: bench_novi | J1: bench | K1: first_prod_date | L1: comp_date | M1: hole_direction | N1: surface_lat | O1: surface_lon
A2: 4231743164 | B2: 42317431640000 | C2: HAYDEN 14-23-A | D2: HAYDEN 14-23-A 4101H | E2: 4101H | F2: XOM | G2: 01PDP | H2: WCA | I2: =IFERROR(_xlfn.XLOOKUP($A2,Novi_Header_for_missingBench_CC!$A:$A,Novi_Header_for_missingBench_CC!$K:$K),"") | J2: WCA | K2: 44348 | L2: 44376 | M2: H | N2: 32.25428 | O2: -101.8415
A3: 4231742907 | B3: 42317429070000 | C3: JACK MOHR UNIT 2 | D3: JACK MOHR UNIT 2 0266DH | E3: 0266DH | F3: XOM | G3: 01PDP | H3: Dean | I3: =IFERROR(_xlfn.XLOOKUP($A3,Novi_Header_for_missingBench_CC!$A:$A,Novi_Header_for_missingBench_CC!$K:$K),"") | J3: Dean | K3: 44593 | L3: 44612 | M3: H | N3: 32.376377 | O3: -101.81657
A4: 4231743195 | B4: 42317431950000 | C4: YOU JANE 20-25 UNIT 1 | D4: YOU JANE 20-25 UNIT 1 112 | E4: 112 | F4: FANG | G4: 01PDP | H4: LSS | I4: =IFERROR(_xlfn.XLOOKUP($A4,Novi_Header_for_missingBench_CC!$A:$A,Novi_Header_for_missingBench_CC!$K:$K),"") | J4: LSS | K4: 44287 | L4: 44314 | M4: H | N4: 32.309669 | O4: -101.98952
A5: 4231743422 | B5: 42317434220000 | C5: MINOTAUR 38-66 UNIT 1 | D5: MINOTAUR 38-66 UNIT 1 142 | E5: 142 | F5: FANG | G5: 01PDP | H5: LSS | I5: =IFERROR(_xlfn.XLOOKUP($A5,Novi_Header_for_missingBench_CC!$A:$A,Novi_Header_for_missingBench_CC!$K:$K),"") | J5: LSS | K5: 44562 | L5: 44568 | M5: H | N5: 32.440754 | O5: -101.8018
A6: 4231739955 | B6: 42317399550100 | C6: MABEE J E `B` NCT-2 | D6: MABEE J E `B` NCT-2 1508H | E6: 1508H | F6: COP | G6: 01PDP | H6: WCB | I6: =IFERROR(_xlfn.XLOOKUP($A6,Novi_Header_for_missingBench_CC!$A:$A,Novi_Header_for_missingBench_CC!$K:$K),"") | J6: WCB | K6: 42186 | L6: 42200 | M6: H | N6: 32.215614 | O6: -102.18284
A7: 4231739048 | B7: 42317390480000 | C7: MABEE 239 | D7: MABEE 239 301WB | E7: 301WB | F7: COP | G7: 01PDP | H7: WCB | I7: =IFERROR(_xlfn.XLOOKUP($A7,Novi_Header_for_missingBench_CC!$A:$A,Novi_Header_for_missingBench_CC!$K:$K),"") | J7: WCB | K7: 41760 | L7: 41758 | M7: H | N7: 32.243214 | O7: -102.16724
A8: 4231738921 | B8: 42317389210000 | C8: GLASSCOCK A5 | D8: GLASSCOCK A5 2H | E8: 2H | F8: XOM | G8: 02PDNP | H8: JM | I8: =IFERROR(_xlfn.XLOOKUP($A8,Novi_Header_for_missingBench_CC!$A:$A,Novi_Header_for_missingBench_CC!$K:$K),"") | J8: JM | K8: 41730 | L8: 41751 | M8: H | N8: 32.121895 | O8: -101.94966
A9: 4231742851 | B9: 42317428510000 | C9: SOUTH CURTIS RANCH 3409AP | D9: SOUTH CURTIS RANCH 3409AP 9H | E9: 9H | F9: OXY | G9: 01PDP | H9: WCB | I9: =IFERROR(_xlfn.XLOOKUP($A9,Novi_Header_for_missingBench_CC!$A:$A,Novi_Header_for_missingBench_CC!$K:$K),"") | J9: WCB | K9: 44256 | L9: 44265 | M9: H | N9: 32.098564 | O9: -102.1181
A10: 4231743054 | B10: 42317430540000 | C10: ROSIE THE ELEPHANT 35-23 A | D10: ROSIE THE ELEPHANT 35-23 A 1LS | E10: 1LS | F10: Birch | G10: 01PDP | H10: LSS | I10: =IFERROR(_xlfn.XLOOKUP($A10,Novi_Header_for_missingBench_CC!$A:$A,Novi_Header_for_missingBench_CC!$K:$K),"") | J10: LSS | K10: 44197 | L10: 44211 | M10: H | N10: 32.091824 | O10: -101.7803
A11: 4231743569 | B11: 42317435690000 | C11: WELCH-COX E39B | D11: WELCH-COX E39B 302H | E11: 302H | F11: XOM | G11: 01PDP | H11: JM | I11: =IFERROR(_xlfn.XLOOKUP($A11,Novi_Header_for_missingBench_CC!$A:$A,Novi_Header_for_missingBench_CC!$K:$K),"") | J11: JM | K11: 45200 | L11: 45218 | M11: H | N11: 32.262005 | O11: -101.93964
A12: 4231739850 | B12: 42317398500000 | C12: JOHNSON RANCH | D12: JOHNSON RANCH 1020LS | E12: 1020LS | F12: COP | G12: 01PDP | H12: LSS | I12: =IFERROR(_xlfn.XLOOKUP($A12,Novi_Header_for_missingBench_CC!$A:$A,Novi_Header_for_missingBench_CC!$K:$K),"") | J12: LSS | K12: 42705 | L12: 42749 | M12: H | N12: 32.165142 | O12: -102.1463
A13: 4231742678 | B13: 42317426780000 | C13: YELLOW PINE E | D13: YELLOW PINE E 6AA | E13: 6AA | F13: OXY | G13: 01PDP | H13: WCA | I13: =IFERROR(_xlfn.XLOOKUP($A13,Novi_Header_for_missingBench_CC!$A:$A,Novi_Header_for_missingBench_CC!$K:$K),"") | J13: WCA | K13: 44470 | L13: 44498 | M13: H | N13: 32.327988 | O13: -101.7107
A14: 4231739065 | B14: 42317390650100 | C14: MABEE 138 | D14: MABEE 138 802HA | E14: 802HA | F14: COP | G14: 01PDP | H14: ATOKA | I14: =IFERROR(_xlfn.XLOOKUP($A14,Novi_Header_for_missingBench_CC!$A:$A,Novi_Header_for_missingBench_CC!$K:$K),"") | J14: ATOKA | K14: 41852 | L14: 41885 | M14: H | N14: 32.204899 | O14: -102.11024
A15: 4231743381 | B15: 42317433810000 | C15: DICKENSON 7-18 WEST | D15: DICKENSON 7-18 WEST 182 | E15: 182 | F15: FANG | G15: 01PDP | H15: LSS | I15: =IFERROR(_xlfn.XLOOKUP($A15,Novi_Header_for_missingBench_CC!$A:$A,Novi_Header_for_missingBench_CC!$K:$K),"") | J15: LSS | K15: 44409 | L15: 44421 | M15: H | N15: 32.229221 | O15: -102.01102
A16: 4231743264 | B16: 42317432640000 | C16: MABEE 30A | D16: MABEE 30A 501HD | E16: 501HD | F16: OVV | G16: 01PDP | H16: JM | I16: =IFERROR(_xlfn.XLOOKUP($A16,Novi_Header_for_missingBench_CC!$A:$A,Novi_Header_for_missingBench_CC!$K:$K),"") | J16: JM | K16: 44287 | L16: 44290 | M16: H | N16: 32.368855 | O16: -102.1812
A17: 4231743405 | B17: 42317434050000 | C17: MADADOR A UNIT | D17: MADADOR A UNIT 2317JM | E17: 2317JM | F17: SM | G17: 01PDP | H17: JM | I17: =IFERROR(_xlfn.XLOOKUP($A17,Novi_Header_for_missingBench_CC!$A:$A,Novi_Header_for_missingBench_CC!$K:$K),"") | J17: JM | K17: 44440 | L17: 44465 | M17: H | N17: 32.474579 | O17: -101.69289
A18: 4231739721 | B18: 42317397210000 | C18: JOHNSON RANCH | D18: JOHNSON RANCH 1023WB | E18: 1023WB | F18: COP | G18: 01PDP | H18: WCB | I18: =IFERROR(_xlfn.XLOOKUP($A18,Novi_Header_for_missingBench_CC!$A:$A,Novi_Header_for_missingBench_CC!$K:$K),"") | J18: WCB | K18: 42125 | L18: 42167 | M18: H | N18: 32.166641 | O18: -102.13976
A19: 4231739458 | B19: 42317394580000 | C19: SALE RANCH `22B` | D19: SALE RANCH `22B` 2H | E19: 2H | F19: XOM | G19: 01PDP | H19: LSS | I19: =IFERROR(_xlfn.XLOOKUP($A19,Novi_Header_for_missingBench_CC!$A:$A,Novi_Header_for_missingBench_CC!$K:$K),"") | J19: LSS | K19: 42125 | L19: 42273 | M19: H | N19: 32.213219 | O19: -101.94164
A20: 4231743407 | B20: 42317434070000 | C20: MADADOR C | D20: MADADOR C 2367WB | E20: 2367WB | F20: SM | G20: 01PDP | H20: WCB | I20: =IFERROR(_xlfn.XLOOKUP($A20,Novi_Header_for_missingBench_CC!$A:$A,Novi_Header_for_missingBench_CC!$K:$K),"") | J20: WCB | K20: 44440 | L20: 44468 | M20: H | N20: 32.474556 | O20: -101.69298
A21: 4231739269 | B21: 42317392690000 | C21: JONES HOLTON | D21: JONES HOLTON 401H | E21: 401H | F21: FANG | G21: 01PDP | H21: WCD | I21: =IFERROR(_xlfn.XLOOKUP($A21,Novi_Header_for_missingBench_CC!$A:$A,Novi_Header_for_missingBench_CC!$K:$K),"") | J21: WCD | K21: 41852 | L21: 41853 | M21: H | N21: 32.375366 | O21: -102.01658
A22: 4231743254 | B22: 42317432540000 | C22: MT LAUREL G | D22: MT LAUREL G 102HA | E22: 102HA | F22: OXY | G22: 01PDP | H22: WCA | I22: =IFERROR(_xlfn.XLOOKUP($A22,Novi_Header_for_missingBench_CC!$A:$A,Novi_Header_for_missingBench_CC!$K:$K),"") | J22: WCA | K22: 44440 | L22: 44451 | M22: H | N22: 32.30719 | O22: -101.70613
A23: 4211533817 | B23: 42115338170000 | C23: STONECREEK UNIT | D23: STONECREEK UNIT M 1H | E23: M 1H | F23: EOG | G23: 01PDP | H23: MSS | I23: =IFERROR(_xlfn.XLOOKUP($A23,Novi_Header_for_missingBench_CC!$A:$A,Novi_Header_for_missingBench_CC!$K:$K),"") | J23: MSS | K23: 44256 | L23: 44263 | M23: H | N23: 32.632065 | O23: -102.03084
A24: 4211533820 | B24: 42115338200000 | C24: NORTHERN HARRIER 20-17 | D24: NORTHERN HARRIER 20-17 1JM | E24: 1JM | F24: Pinon | G24: 02PDNP | H24: JM | I24: =IFERROR(_xlfn.XLOOKUP($A24,Novi_Header_for_missingBench_CC!$A:$A,Novi_Header_for_missingBench_CC!$K:$K),"") | J24: JM | K24: 44256 | L24: 44285 | M24: H | N24: 32.591927 | O24: -101.78908
A25: 4231743143 | B25: 42317431430000 | C25: MABEE BREEDLOVE | D25: MABEE BREEDLOVE 2101LS | E25: 2101LS | F25: FANG | G25: 01PDP | H25: LSS | I25: =IFERROR(_xlfn.XLOOKUP($A25,Novi_Header_for_missingBench_CC!$A:$A,Novi_Header_for_missingBench_CC!$K:$K),"") | J25: LSS | K25: 44593 | L25: 44586 | M25: H | N25: 32.434906 | O25: -102.1554
A26: 4231743244 | B26: 42317432440000 | C26: JOHNSON RANCH | D26: JOHNSON RANCH 404JH | E26: 404JH | F26: COP | G26: 01PDP | H26: JM | I26: =IFERROR(_xlfn.XLOOKUP($A26,Novi_Header_for_missingBench_CC!$A:$A,Novi_Header_for_missingBench_CC!$K:$K),"") | J26: JM | K26: 44927 | L26: 44953 | M26: H | N26: 32.175995 | O26: -102.16341
A27: 4231742712 | B27: 42317427120000 | C27: T Y RANCH WEST | D27: T Y RANCH WEST 2453WB | E27: 2453WB | F27: FANG | G27: 01PDP | H27: JM | I27: =IFERROR(_xlfn.XLOOKUP($A27,Novi_Header_for_missingBench_CC!$A:$A,Novi_Header_for_missingBench_CC!$K:$K),"") | J27: JM | K27: 44835 | L27: 44855 | M27: H | N27: 32.383705 | O27: -101.99884
... A31: 4231739387 | B31: 42317393870000 | C31: WOLCOTT 253 | D31: WOLCOTT 253 1H | E31: 1H | F31: OVV | G31: 01PDP | H31: WCB | I31: =IFERROR(_xlfn.XLOOKUP($A31,Novi_Header_for_missingBench_CC!$A:$A,Novi_Header_for_missingBench_CC!$K:$K),"") | J31: WCB | K31: 41883 | L31: 41889 | M31: H | N31: 32.469456 | O31: -101.98578
A32: 4231743274 | B32: 42317432740000 | C32: STEUBEN 3 | D32: STEUBEN 3 302 | E32: 302 | F32: FANG | G32: 01PDP | H32: WCA | I32: =IFERROR(_xlfn.XLOOKUP($A32,Novi_Header_for_missingBench_CC!$A:$A,Novi_Header_for_missingBench_CC!$K:$K),"") | J32: WCA | K32: 44682 | L32: 44689 | M32: H | N32: 32.237564 | O32: -101.73781
A33: 4231742618 | B33: 42317426180000 | C33: BIG JAY 10-15 B | D33: BIG JAY 10-15 B 2DN | E33: 2DN | F33: Birch | G33: 01PDP | H33: Dean | I33: =IFERROR(_xlfn.XLOOKUP($A33,Novi_Header_for_missingBench_CC!$A:$A,Novi_Header_for_missingBench_CC!$K:$K),"") | J33: Dean | K33: 44348 | L33: 44365 | M33: H | N33: 32.287487 | O33: -101.76183
A34: 4231743393 | B34: 42317433930000 | C34: UL COMANCHE I 29-42 | D34: UL COMANCHE I 29-42 3MS | E34: 3MS | F34: FANG | G34: 01PDP | H34: MSS | I34: =IFERROR(_xlfn.XLOOKUP($A34,Novi_Header_for_missingBench_CC!$A:$A,Novi_Header_for_missingBench_CC!$K:$K),"") | J34: MSS | K34: 44593 | L34: 44609 | M34: H | N34: 32.483192 | O34: -102.18759
A35: 4231743184 | B35: 42317431840000 | C35: JIM TOM 29A | D35: JIM TOM 29A 1H | E35: 1H | F35: XOM | G35: 01PDP | H35: WCA | I35: =IFERROR(_xlfn.XLOOKUP($A35,Novi_Header_for_missingBench_CC!$A:$A,Novi_Header_for_missingBench_CC!$K:$K),"") | J35: WCA | K35: 44256 | L35: 44283 | M35: H | N35: 32.110443 | O35: -101.73927
A36: 4231743503 | B36: 42317435030000 | C36: WOODY 31C | D36: WOODY 31C 3H | E36: 3H | F36: XOM | G36: 01PDP | H36: WCB | I36: =IFERROR(_xlfn.XLOOKUP($A36,Novi_Header_for_missingBench_CC!$A:$A,Novi_Header_for_missingBench_CC!$K:$K),"") | J36: WCB | K36: 44743 | L36: 44773 | M36: H | N36: 32.274067 | O36: -101.96071
A37: 4231738835 | B37: 42317388350000 | C37: CURTIS RANCH SOUTH | D37: CURTIS RANCH SOUTH 3520H | E37: 3520H | F37: OXY | G37: 01PDP | H37: WCB | I37: =IFERROR(_xlfn.XLOOKUP($A37,Novi_Header_for_missingBench_CC!$A:$A,Novi_Header_for_missingBench_CC!$K:$K),"") | J37: WCB | K37: 41699 | L37: 41689 | M37: H | N37: 32.110207 | O37: -102.10311
A38: 4231741522 | B38: 42317415220000 | C38: THIRSTY GOAT E UNIT | D38: THIRSTY GOAT E UNIT 1WA | E38: 1WA | F38: OVV | G38: 01PDP | H38: WCA | I38: =IFERROR(_xlfn.XLOOKUP($A38,Novi_Header_for_missingBench_CC!$A:$A,Novi_Header_for_missingBench_CC!$K:$K),"") | J38: WCA | K38: 44166 | L38: 44147 | M38: H | N38: 32.465279 | O38: -101.82525
A39: 4231742460 | B39: 42317424600000 | C39: DARK STAR UNIT 1 | D39: DARK STAR UNIT 1 2123SH | E39: 2123SH | F39: XOM | G39: 01PDP | H39: LSS | I39: =IFERROR(_xlfn.XLOOKUP($A39,Novi_Header_for_missingBench_CC!$A:$A,Novi_Header_for_missingBench_CC!$K:$K),"") | J39: LSS | K39: 44287 | L39: 44331 | M39: H | N39: 32.269638 | O39: -101.77313
A40: 4231741656 | B40: 42317416560000 | C40: NORTHEAST SCHARBAUER | D40: NORTHEAST SCHARBAUER 1217H | E40: 1217H | F40: XOM | G40: 01PDP | H40: LSS | I40: =IFERROR(_xlfn.XLOOKUP($A40,Novi_Header_for_missingBench_CC!$A:$A,Novi_Header_for_missingBench_CC!$K:$K),"") | J40: LSS | K40: 44805 | L40: 44805 | M40: H | N40: 32.286781 | O40: -102.08073
A41: 4231743489 | B41: 42317434890000 | C41: BLACK LAGOON 2-3 UNIT 2 | D41: BLACK LAGOON 2-3 UNIT 2 264 | E41: 264 | F41: FANG | G41: 01PDP | H41: WCA | I41: =IFERROR(_xlfn.XLOOKUP($A41,Novi_Header_for_missingBench_CC!$A:$A,Novi_Header_for_missingBench_CC!$K:$K),"") | J41: WCA | K41: 44562 | L41: 44563 | M41: H | N41: 32.235786 | O41: -102.04698
A42: 4231743542 | B42: 42317435420000 | C42: WELCH-COX W39L | D42: WELCH-COX W39L 212H | E42: 212H | F42: XOM | G42: 01PDP | H42: LSS | I42: =IFERROR(_xlfn.XLOOKUP($A42,Novi_Header_for_missingBench_CC!$A:$A,Novi_Header_for_missingBench_CC!$K:$K),"") | J42: LSS | K42: 44927 | L42: 44953 | M42: H | N42: 32.260189 | O42: -101.94772
A43: 4231742555 | B43: 42317425550000 | C43: KNOX 3 | D43: KNOX 3 102 | E43: 102 | F43: FANG | G43: 01PDP | H43: WCB | I43: =IFERROR(_xlfn.XLOOKUP($A43,Novi_Header_for_missingBench_CC!$A:$A,Novi_Header_for_missingBench_CC!$K:$K),"") | J43: WCB | K43: 44378 | L43: 44392 | M43: H | N43: 32.113594 | O43: -101.79185
...

Sheet Novi_Header_for_missingBench_CC
A1: API10/UWI | B1: Name | C1: Direction | D1: Type | E1: Original Operator | F1: Current Operator | G1: Current Operator Entity | H1: Last Well Status | I1: Reported Well Status | J1: Lease ID | K1: Formation | L1: Reported Formation | M1: Grid Formation | N1: TVD | O1: TVDSS | P1: MD | Q1: Altitude | R1: Ticker | S1: Is Public
A2: 4213543411 | B2: EDWARDS 31 8HA | C2: Horizontal | D2: Oil | E2: Adventure Operating Company | F2: Adventure Operating Company | G2: ADVENTURE OPERATING COMPANY, LLC | H2: Plugged | J2: 08;48245 | K2: SAN ANDRES | L2: San Andres | N2: 4104 | O2: 1187 | P2: 9341 | Q2: 2917 | S2: f
A3: 4213543764 | B3: RED BARCHETTA 30-19 1BN | C3: Horizontal | D3: Oil | E3: Diamondback | F3: Diamondback | G3: DIAMONDBACK E&P LLC | H3: Producing | J3: 08;62612 | K3: SUB-WOODFORD | L3: Dean | M3: Sub-Woodford | N3: 10782 | O3: 7829 | P3: 21463 | Q3: 2953 | R3: FANG | S3: t
A4: 4213543852 | B4: TERRY 1H | C4: Horizontal | D4: Oil | E4: Ares Energy | F4: Ares Energy | G4: ARES ENERGY, LTD. | H4: Producing | J4: 08;60726 | K4: MISSISSIPPIAN | L4: Wolfcamp | M4: Mississippian | N4: 11692 | O4: 8582 | P4: 22382 | Q4: 3110 | S4: f
A5: 4213543894 | B5: TOM SAWYER 43-6 C 4BN | C5: Horizontal | D5: Oil | E5: Diamondback | F5: Diamondback | G5: DIAMONDBACK E&P LLC | H5: Producing | J5: 08;59507 | K5: BARNETT | L5: Dean | M5: Barnett | N5: 10481 | O5: 7597 | P5: 21415 | Q5: 2884 | R5: FANG | S5: t
A6: 4213543897 | B6: H.S. RATLIFF 85-17A 1H | C6: Horizontal | D6: Oil | E6: Continental Resources | F6: Continental Resources | G6: CONTINENTAL RESOURCES, INC. | H6: Producing | J6: 08;59003 | K6: MISSISSIPPIAN | L6: Dean | M6: Mississippian | N6: 11589 | O6: 8544 | P6: 21793 | Q6: 3045 | R6: CLR | S6: t
A7: 4213543905 | B7: JF COWDEN 18 1H | C7: Horizontal | D7: Oil | E7: Maverick Natural Resources | F7: Diversified Energy | G7: MAVERICK PERMIAN LLC | H7: Producing | J7: 08;60050 | K7: WICHITA | L7: Wichita | N7: 6617 | O7: 3398 | P7: 12138 | Q7: 3219 | R7: DECPF | S7: t
A8: 4213543906 | B8: JF COWDEN 08X05 1H | C8: Horizontal | D8: Oil | E8: Maverick Natural Resources | F8: Diversified Energy | G8: MAVERICK PERMIAN LLC | H8: Producing | J8: 08;60080 | K8: WICHITA | L8: Wichita | N8: 6759 | O8: 3540 | P8: 17270 | Q8: 3219 | R8: DECPF | S8: t
A9: 4213543916 | B9: JF COWDEN 07X06 1H | C9: Horizontal | D9: Oil | E9: Maverick Natural Resources | F9: Diversified Energy | G9: MAVERICK PERMIAN LLC | H9: Producing | J9: 08;60079 | K9: WICHITA | L9: Wichita | N9: 6803 | O9: 3584 | P9: 17103 | Q9: 3219 | R9: DECPF | S9: t
A10: 4213543917 | B10: JF COWDEN 07X18 1H | C10: Horizontal | D10: Oil | E10: Maverick Natural Resources | F10: Diversified Energy | G10: MAVERICK PERMIAN LLC | H10: Producing | J10: 08;61053 | K10: WICHITA | L10: Wichita | N10: 6673 | O10: 3428 | P10: 17454 | Q10: 3245 | R10: DECPF | S10: t
A11: 4213544016 | B11: KATY UNIT 1H | C11: Horizontal | D11: Oil | E11: Ares Energy | F11: Ares Energy | G11: ARES ENERGY, LTD. | H11: Producing | J11: 08;62844 | K11: MISSISSIPPIAN | L11: Wolfcamp | M11: Mississippian | N11: 11260 | O11: 8189 | P11: 23220 | Q11: 3071 | S11: f
A12: 4213544063 | B12: GARDENDALE 12-1 01WB | C12: Horizontal | D12: Oil | E12: Slant Operating | F12: Slant Operating | G12: SLANT OPERATING, LLC | H12: Producing | K12: WOLFCAMP A | L12: Wolfcamp | M12: Wolfcamp A | N12: 8940 | O12: 5954 | P12: 19313 | Q12: 2986 | S12: f
A13: 4216538850 | B13: NORTH RILEY UNIT 2340H | C13: Horizontal | D13: Oil | E13: Sabinal Energy | F13: Sabinal Energy | G13: SABINAL ENERGY OPERATING, LLC | H13: Producing | J13: 8A;61559 | K13: UNKNOWN | L13: Other | N13: 6889 | O13: 3460 | P13: 12393 | Q13: 3429 | S13: f
A14: 4216538856 | B14: RUIDOSA 365 1H | C14: Horizontal | D14: Oil | E14: Sabinal Energy | F14: Sabinal Energy | G14: SABINAL ENERGY OPERATING, LLC | H14: Producing | J14: 8A;71291 | K14: SPRABERRY | L14: Spraberry | N14: 6793 | O14: 3341 | P14: 12254 | Q14: 3452 | S14: f
A15: 4216538858 | B15: NORTH RILEY UNIT 2330H | C15: Horizontal | D15: Oil | E15: Sabinal Energy | F15: Sabinal Energy | G15: SABINAL ENERGY OPERATING, LLC | H15: Producing | J15: 8A;61559 | K15: SPRABERRY | L15: Spraberry | N15: 6909 | O15: 3480 | P15: 13183 | Q15: 3429 | S15: f
A16: 4216538877 | B16: BISHOP DONAHUE FEE 1H | C16: Horizontal | D16: Oil | E16: Manzano | F16: Manzano | G16: MANZANO, LLC | H16: Producing | J16: 8A;71295 | K16: SPRABERRY | L16: Spraberry | N16: 8186 | O16: 4679 | P16: 17081 | Q16: 3507 | S16: f
A17: 4216538881 | B17: NORTH RILEY UNIT 2335H | C17: Horizontal | D17: Oil | E17: Sabinal Energy | F17: Sabinal Energy | G17: SABINAL ENERGY OPERATING, LLC | H17: Producing | J17: 8A;61559 | K17: SPRABERRY | L17: Spraberry | N17: 6879 | O17: 3450 | P17: 13025 | Q17: 3429 | S17: f
A18: 4216538884 | B18: SCRAMBLER A 5H | C18: Horizontal | D18: Oil | E18: Joint Resources | F18: Joint Resources | G18: JOINT RESOURCES COMPANY | H18: Producing | J18: 8A;70970 | K18: SAN ANDRES | L18: San Andres | N18: 5578 | O18: 1943 | P18: 12457 | Q18: 3635 | S18: f
A19: 4216538933 | B19: BLANTON 2325H | C19: Horizontal | D19: Oil | E19: Sabinal Energy | F19: Sabinal Energy | G19: SABINAL ENERGY OPERATING, LLC | H19: Producing | J19: 8A;71379 | K19: SPRABERRY | L19: Spraberry | N19: 6910 | O19: 3471 | P19: 16102 | Q19: 3439 | S19: f
A20: 4216538934 | B20: SHINER 2315H | C20: Horizontal | D20: Oil | E20: Sabinal Energy | F20: Sabinal Energy | G20: SABINAL ENERGY OPERATING, LLC | H20: Producing | J20: 8A;71385 | K20: SPRABERRY | L20: Spraberry | N20: 6889 | O20: 3450 | P20: 16059 | Q20: 3439 | S20: f
A21: 4200347862 | B21: UL 14 OBERON 5H | C21: Horizontal | D21: Oil | E21: Lime Rock Resources IV | F21: Ring Energy | G21: RING ENERGY, INC. | H21: Producing | J21: 08;46617 | K21: SAN ANDRES | L21: San Andres | N21: 4692 | O21: 1395 | P21: 10084 | Q21: 3297 | R21: REI | S21: t
A22: 4200347919 | B22: UNIVERSITY BLOCK 9 G MS 2H | C22: Horizontal | D22: Oil | E22: Exxon Mobil | F22: Exxon Mobil | G22: XTO ENERGY INC. | H22: Producing | J22: 08;52174 | K22: MISSISSIPPIAN | L22: Wolfcamp | M22: Mississippian | N22: 10392 | O22: 7229 | P22: 21417 | Q22: 3163 | R22: XOM | S22: t
A23: 4200347982 | B23: UNIVERSITY BLOCK 14 CONS. 2501XH | C23: Horizontal | D23: Oil | E23: Ring Energy | F23: Ring Energy | G23: RING ENERGY, INC. | H23: Producing | J23: 08;29524 | K23: SAN ANDRES | L23: San Andres | N23: 4751 | O23: 1503 | P23: 12550 | Q23: 3248 | R23: REI | S23: t
A24: 4200347985 | B24: UNIVERSITY BLOCK 14 CONS. 2506XH | C24: Horizontal | D24: Oil | E24: Ring Energy | F24: Ring Energy | G24: RING ENERGY, INC. | H24: Producing | J24: 08;29524 | K24: SAN ANDRES | L24: San Andres | N24: 4773 | O24: 1518 | P24: 12570 | Q24: 3255 | R24: REI | S24: t
A25: 4200348009 | B25: HADES 1H | C25: Horizontal | D25: Oil | E25: Ring Energy | F25: Ring Energy | G25: RING ENERGY, INC. | H25: Producing | J25: 08;60724 | K25: SAN ANDRES | L25: San Andres | N25: 4728 | O25: 1509 | P25: 10152 | Q25: 3219 | R25: REI | S25: t
A26: 4200348011 | B26: HEBE 1H | C26: Horizontal | D26: Oil | E26: Ring Energy | F26: Ring Energy | G26: RING ENERGY, INC. | H26: Producing | J26: 08;60725 | K26: SAN ANDRES | L26: San Andres | N26: 4697 | O26: 1468 | P26: 10105 | Q26: 3229 | R26: REI | S26: t
A27: 4200348043 | B27: UNIVERSITY 14SQ 1402H | C27: Horizontal | D27: Oil | E27: Ring Energy | F27: Ring Energy | G27: RING ENERGY, INC. | H27: Producing | J27: 08;61529 | K27: SAN ANDRES | L27: San Andres | N27: 4665 | O27: 1394 | P27: 10242 | Q27: 3271 | R27: REI | S27: t
A28: 4200348048 | B28: UNIVERSITY 14SR 1404H | C28: Horizontal | D28: Oil | E28: Ring Energy | F28: Ring Energy | G28: RING ENERGY, INC. | H28: Producing | J28: 08;62804 | K28: SAN ANDRES | L28: San Andres | N28: 4676 | O28: 1392 | P28: 10163 | Q28: 3284 | R28: REI | S28: t
A29: 4200348072 | B29: UNIVERSITY BLOCK 14 CONS. 2401H | C29: Horizontal | D29: Oil | E29: Ring Energy | F29: Ring Energy | G29: RING ENERGY, INC. | H29: Producing | J29: 08;29524 | K29: SAN ANDRES | L29: San Andres | N29: 4772 | O29: 1534 | P29: 10115 | Q29: 3238 | R29: REI | S29: t
A30: 4200348073 | B30: UNIVERSITY BLOCK 14 CONS. 2403H | C30: Horizontal | D30: Oil | E30: Ring Energy | F30: Ring Energy | G30: RING ENERGY, INC. | H30: Producing | J30: 08;29524 | K30: SAN ANDRES | L30: San Andres | N30: 4768 | O30: 1533 | P30: 10168 | Q30: 3235 | R30: REI | S30: t
A31: 4200348600 | B31: UL G 9-33 B 2H | C31: Horizontal | D31: Oil | E31: Elevation Resources | F31: Elevation Resources | G31: ELEVATION RESOURCES LLC | H31: Producing | J31: 08;59853 | K31: MISSISSIPPIAN | L31: Wolfcamp | M31: Mississippian | N31: 10101 | O31: 6908 | P31: 17045 | Q31: 3193 | S31: f
A32: 4200348655 | B32: UL G 9-25 D 4H | C32: Horizontal | D32: Oil | E32: Elevation Resources | F32: Elevation Resources | G32: ELEVATION RESOURCES LLC | H32: Producing | J32: 08;296524 | K32: MISSISSIPPIAN | L32: Wolfcamp | M32: Mississippian | N32: 10439 | O32: 7302 | P32: 23318 | Q32: 3137 | S32: f
A33: 4200348694 | B33: DEEP ROCK 23 1H | C33: Horizontal | D33: Oil | E33: Ica Energy | F33: Ica Energy | G33: ICA ENERGY OPERATING, L.L.C. | H33: Producing | J33: 08;61090 | K33: SAN ANDRES | L33: San Andres | N33: 4284 | O33: 1046 | P33: 9479 | Q33: 3238 | S33: f
A34: 4200348761 | B34: ZENA 1XH | C34: Horizontal | D34: Oil | E34: Ring Energy | F34: Ring Energy | G34: RING ENERGY, INC. | H34: Producing | J34: 08;60917 | K34: SAN ANDRES | L34: San Andres | N34: 4684 | O34: 1478 | P34: 12797 | Q34: 3206 | R34: REI | S34: t
A35: 4200348762 | B35: ZENA WP 2XH | C35: Horizontal | D35: Oil | E35: Ring Energy | F35: Ring Energy | G35: RING ENERGY, INC. | H35: Producing | J35: 08;60918 | K35: SAN ANDRES | L35: San Andres | N35: 4695 | O35: 1486 | P35: 12795 | Q35: 3209 | R35: REI | S35: t
A36: 4200348806 | B36: UNIVERSITY A12 2H | C36: Horizontal | D36: Oil | E36: Custer & Wright Operating | F36: Custer & Wright Operating | G36: CUSTER & WRIGHT OPERATING, INC. | H36: Producing | J36: 08;58804 | K36: GRAYBURG | L36: Grayburg | N36: 4356 | O36: 1111 | P36: 10351 | Q36: 3245 | S36: f
A37: 4200348819 | B37: DEEP ROCK 23 2H | C37: Horizontal | D37: Oil | E37: Ica Energy | F37: Ica Energy | G37: ICA ENERGY OPERATING, L.L.C. | H37: Producing | J37: 08;61090 | K37: GRAYBURG | L37: Grayburg | N37: 4278 | O37: 1059 | P37: 9427 | Q37: 3219 | S37: f
A38: 4200348820 | B38: DEEP ROCK 23 3H | C38: Horizontal | D38: Oil | E38: Ica Energy | F38: Ica Energy | G38: ICA ENERGY OPERATING, L.L.C. | H38: Producing | J38: 08;61090 | K38: GRAYBURG | L38: Grayburg | N38: 4284 | O38: 1039 | P38: 9318 | Q38: 3245 | S38: f
A39: 4200348838 | B39: UL G 9-48 C 3H | C39: Horizontal | D39: Oil | E39: Elevation Resources | F39: Elevation Resources | G39: ELEVATION RESOURCES LLC | H39: Producing | J39: 08;61528 | K39: MISSISSIPPIAN | L39: Wolfcamp | M39: Mississippian | N39: 10756 | O39: 7642 | P39: 18250 | Q39: 3114 | S39: f
A40: 4200348839 | B40: UL G 9-48 D 4H | C40: Horizontal | D40: Oil | E40: Elevation Resources | F40: Elevation Resources | G40: ELEVATION RESOURCES LLC | H40: Producing | J40: 08;61322 | K40: MISSISSIPPIAN | L40: Wolfcamp | M40: Mississippian | N40: 10785 | O40: 7671 | P40: 18230 | Q40: 3114 | S40: f
...
